<?xml version="1.0" encoding="utf-8"?>
<mujoco model="gait10dof18musc.osim">
  <compiler inertiafromgeom="auto" angle="radian" balanceinertia="true" boundmass="0.001" boundinertia="0.001">
    <lengthrange inttotal="500"></lengthrange>
  </compiler>
  <default>
    <joint limited="true" damping="0.5" armature="0.01" stiffness="0"></joint>
    <geom contype="1" conaffinity="1" condim="3" rgba="0.8 0.6 .4 1" margin="0.001" solref=".02 1" solimp=".8 .8 .01" material="geom"></geom>
    <site size="0.001"></site>
    <tendon width="0.001" rgba=".95 .3 .3 1" limited="false"></tendon>
    <default class="muscle">
      <muscle ctrllimited="true" ctrlrange="0 1" scale="400"></muscle>
    </default>
    <default class="motor">
      <motor gear="20"></motor>
    </default>
  </default>
  <option timestep="0.002">
    <flag energy="enable"></flag>
  </option>
  <size njmax="1000" nconmax="400" nuser_jnt="1"></size>
  <visual>
    <map fogstart="3" fogend="5" force="0.1"></map>
    <quality shadowsize="2048"></quality>
  </visual>
  <worldbody>
    <geom name="floor" pos="0 0 0" size="10 10 0.125" type="plane" material="MatPlane" condim="3"></geom>
    <body name="pelvis" pos="       0    -0.02 1.22465e-18" quat="0.7071067811865475 0.7071067811865475 0.0 0.0">
      <light mode="trackcom" directional="false" diffuse=".8 .8 .8" specular="0.3 0.3 0.3" pos="0 0 4.0" dir="0 0 -1"></light>
      <geom name="sacrum" type="mesh" mesh="sacrum"></geom>
      <geom name="pelvis" type="mesh" mesh="pelvis"></geom>
      <geom name="l_pelvis" type="mesh" mesh="l_pelvis"></geom>
      <inertial pos=" -0.0707        0        0" mass="11.777" fullinertia="  0.1028   0.0871   0.0579        0        0        0"></inertial>
      <site name="bifemlh_r-P1" pos="-0.12596 -0.10257 0.06944"></site>
      <site name="glut_max_r-P1" pos="-0.1317 0.0087 0.0462"></site>
      <site name="glut_max_r-P2" pos="-0.1344 -0.0609 0.0813"></site>
      <site name="psoas_r-P1" pos="-0.0647 0.0887 0.0289"></site>
      <site name="psoas_r-P2" pos="-0.0238 -0.057 0.0759"></site>
      <site name="rect_fem_r-P1" pos="-0.0295 -0.0311 0.0968"></site>
      <site name="bifemlh_l-P1" pos="-0.12596 -0.10257 -0.06944"></site>
      <site name="glut_max_l-P1" pos="-0.1317 0.0087 -0.0462"></site>
      <site name="glut_max_l-P2" pos="-0.1344 -0.0609 -0.0813"></site>
      <site name="psoas_l-P1" pos="-0.0647 0.0887 -0.0289"></site>
      <site name="psoas_l-P2" pos="-0.0238 -0.057 -0.0759"></site>
      <site name="rect_fem_l-P1" pos="-0.0295 -0.0311 -0.0968"></site>
      <joint name="pelvis_ty" type="slide" pos="0 0 0" axis="       0        1        0" limited="false" range="      -1        2" ref="0" armature="0" damping="0" stiffness="0"></joint>
      <joint name="pelvis_tx" type="slide" pos="0 0 0" axis="       1        0        0" limited="false" range="      -5        5" ref="0" armature="0" damping="0" stiffness="0"></joint>
      <joint name="pelvis_tilt" type="hinge" pos="0 0 0" axis="       0        0        1" limited="false" range=" -1.5708   1.5708" ref="0" armature="0" damping="0" stiffness="0"></joint>
      <body name="femur_r" pos=" -0.0707  -0.0661   0.0835" quat="1.0 0.0 0.0 0.0">
        <geom name="femur" type="mesh" mesh="femur"></geom>
        <inertial pos="       0    -0.17        0" mass="9.3014" fullinertia="  0.1339   0.0351   0.1412        0        0        0"></inertial>
        <site name="bifemsh_r-P1" pos="0.005 -0.2111 0.0234"></site>
        <site name="glut_max_r-P3" pos="-0.045 -0.0584 0.0252"></site>
        <site name="glut_max_r-P4" pos="-0.0156 -0.1016 0.0419"></site>
        <site name="psoas_r-P4" pos="0.0016 -0.0507 0.0038"></site>
        <site name="psoas_r-P5" pos="-0.0188 -0.0597 0.0104"></site>
        <site name="vas_int_r-P1" pos="0.029 -0.1924 0.031"></site>
        <site name="vas_int_r-P2" pos="0.0335 -0.2084 0.0285"></site>
        <site name="med_gas_r-P1" pos="-0.019 -0.3929 -0.0235"></site>
        <joint name="hip_flexion_r" type="hinge" pos="0 0 0" axis="       0        0        1" limited="false" range=" -2.0944   2.0944" ref="0"></joint>
        <body name="tibia_r" pos="       0        0        0" quat="1.0 0.0 0.0 0.0">
          <geom name="tibia" type="mesh" mesh="tibia"></geom>
          <geom name="fibula" type="mesh" mesh="fibula"></geom>
          <inertial pos="       0  -0.1867        0" mass="3.7075" fullinertia="  0.0504   0.0051   0.0511        0        0        0"></inertial>
          <site name="bifemlh_r-P2" pos="-0.0301 -0.036 0.02943"></site>
          <site name="bifemlh_r-P3" pos="-0.0234 -0.0563 0.0343"></site>
          <site name="bifemsh_r-P2" pos="-0.0301 -0.036 0.02943"></site>
          <site name="bifemsh_r-P3" pos="-0.0234 -0.0563 0.0343"></site>
          <site name="rect_fem_r-P3" pos="0.0780827 -0.0123631   0.0014"></site>
          <site name="vas_int_r-P4" pos="0.0785259 -0.00619903   0.0018"></site>
          <site name="soleus_r-P1" pos="-0.0024 -0.1533 0.0071"></site>
          <site name="tib_ant_r-P1" pos="0.0179 -0.1624 0.0115"></site>
          <site name="tib_ant_r-P2" pos="0.0329 -0.3951 -0.0177"></site>
          <joint name="knee_angle_r_translation2" type="slide" pos="0 0 0" axis="       0        1        0" limited="true" range="-0.422602 -0.395309" ref="0"></joint>
          <joint name="knee_angle_r_translation1" type="slide" pos="0 0 0" axis="       1        0        0" limited="true" range="-0.00591791 0.00435888" ref="0"></joint>
          <joint name="knee_angle_r" type="hinge" pos="0 0 0" axis="       0        0        1" limited="false" range=" -2.0944 0.174533" ref="0"></joint>
          <body name="talus_r" pos="       0    -0.43        0" quat="1.0 0.0 0.0 0.0">
            <geom name="talus" type="mesh" mesh="talus"></geom>
            <inertial pos="       0        0        0" mass="0.1" fullinertia="   0.001    0.001    0.001        0        0        0"></inertial>
            <joint name="ankle_angle_r" type="hinge" pos="0 0 0" axis="       0        0        1" limited="false" range=" -1.5708   1.5708" ref="0"></joint>
            <body name="calcn_r" pos="-0.04877 -0.04195  0.00792" quat="1.0 0.0 0.0 0.0">
              <geom name="foot" type="mesh" mesh="foot"></geom>
              <inertial pos="     0.1     0.03        0" mass="1.25" fullinertia="  0.0014   0.0039   0.0041        0        0        0"></inertial>
              <site name="med_gas_r-P3" pos="0 0.031 -0.0053"></site>
              <site name="soleus_r-P2" pos="0 0.031 -0.0053"></site>
              <site name="tib_ant_r-P3" pos="0.1166 0.0178 -0.0305"></site>
              <body name="toes_r" pos="  0.1788   -0.002  0.00108" quat="1.0 0.0 0.0 0.0">
                <geom name="bofoot" type="mesh" mesh="bofoot"></geom>
                <inertial pos="  0.0346    0.006  -0.0175" mass="0.2166" fullinertia="  0.0001   0.0002   0.0001        0        0        0"></inertial>
              </body>
            </body>
          </body>
        </body>
      </body>
      <body name="femur_l" pos=" -0.0707  -0.0661  -0.0835" quat="1.0 0.0 0.0 0.0">
        <geom name="l_femur" type="mesh" mesh="l_femur"></geom>
        <inertial pos="       0    -0.17        0" mass="9.3014" fullinertia="  0.1339   0.0351   0.1412        0        0        0"></inertial>
        <site name="bifemsh_l-P1" pos="0.005 -0.2111 -0.0234"></site>
        <site name="glut_max_l-P3" pos="-0.045 -0.0584 -0.0252"></site>
        <site name="glut_max_l-P4" pos="-0.0156 -0.1016 -0.0419"></site>
        <site name="psoas_l-P4" pos="0.0016 -0.0507 -0.0038"></site>
        <site name="psoas_l-P5" pos="-0.0188 -0.0597 -0.0104"></site>
        <site name="vas_int_l-P1" pos="0.029 -0.1924 -0.031"></site>
        <site name="vas_int_l-P2" pos="0.0335 -0.2084 -0.0285"></site>
        <site name="med_gas_l-P1" pos="-0.019 -0.3929 0.0235"></site>
        <joint name="hip_flexion_l" type="hinge" pos="0 0 0" axis="       0        0        1" limited="false" range=" -2.0944   2.0944" ref="0"></joint>
        <body name="tibia_l" pos="       0        0        0" quat="1.0 0.0 0.0 0.0">
          <geom name="l_tibia" type="mesh" mesh="l_tibia"></geom>
          <geom name="l_fibula" type="mesh" mesh="l_fibula"></geom>
          <inertial pos="       0  -0.1867        0" mass="3.7075" fullinertia="  0.0504   0.0051   0.0511        0        0        0"></inertial>
          <site name="bifemlh_l-P2" pos="-0.0301 -0.036 -0.02943"></site>
          <site name="bifemlh_l-P3" pos="-0.0234 -0.0563 -0.0343"></site>
          <site name="bifemsh_l-P2" pos="-0.0301 -0.036 -0.02943"></site>
          <site name="bifemsh_l-P3" pos="-0.0234 -0.0563 -0.0343"></site>
          <site name="rect_fem_l-P3" pos="0.0780827 -0.0123631  -0.0014"></site>
          <site name="vas_int_l-P4" pos="0.0785259 -0.00619903  -0.0018"></site>
          <site name="soleus_l-P1" pos="-0.0024 -0.1533 -0.0071"></site>
          <site name="tib_ant_l-P1" pos="0.0179 -0.1624 -0.0115"></site>
          <site name="tib_ant_l-P2" pos="0.0329 -0.3951 0.0177"></site>
          <joint name="knee_angle_l_translation2" type="slide" pos="0 0 0" axis="       0        1        0" limited="true" range="-0.422602 -0.395309" ref="0"></joint>
          <joint name="knee_angle_l_translation1" type="slide" pos="0 0 0" axis="       1        0        0" limited="true" range="-0.00591791 0.00435888" ref="0"></joint>
          <joint name="knee_angle_l" type="hinge" pos="0 0 0" axis="       0        0        1" limited="false" range=" -2.0944 0.174533" ref="0"></joint>
          <body name="talus_l" pos="       0    -0.43        0" quat="1.0 0.0 0.0 0.0">
            <geom name="l_talus" type="mesh" mesh="l_talus"></geom>
            <inertial pos="       0        0        0" mass="0.1" fullinertia="   0.001    0.001    0.001        0        0        0"></inertial>
            <joint name="ankle_angle_l" type="hinge" pos="0 0 0" axis="       0        0        1" limited="false" range=" -1.0472   1.0472" ref="0"></joint>
            <body name="calcn_l" pos="-0.04877 -0.04195 -0.00792" quat="1.0 0.0 0.0 0.0">
              <geom name="l_foot" type="mesh" mesh="l_foot"></geom>
              <inertial pos="     0.1     0.03        0" mass="1.25" fullinertia="  0.0014   0.0039   0.0041        0        0        0"></inertial>
              <site name="med_gas_l-P3" pos="0 0.031 0.0053"></site>
              <site name="soleus_l-P2" pos="0 0.031 0.0053"></site>
              <site name="tib_ant_l-P3" pos="0.1166 0.0178 0.0305"></site>
              <body name="toes_l" pos="  0.1788   -0.002 -0.00108" quat="1.0 0.0 0.0 0.0">
                <geom name="l_bofoot" type="mesh" mesh="l_bofoot"></geom>
                <inertial pos="  0.0346    0.006   0.0175" mass="0.2166" fullinertia="  0.0001   0.0002   0.0001        0        0        0"></inertial>
              </body>
            </body>
          </body>
        </body>
      </body>
      <body name="torso" pos=" -0.1007   0.0815        0" quat="1.0 0.0 0.0 0.0">
        <geom name="hat_spine" type="mesh" mesh="hat_spine"></geom>
        <geom name="hat_jaw" type="mesh" mesh="hat_jaw"></geom>
        <geom name="hat_skull" type="mesh" mesh="hat_skull"></geom>
        <geom name="hat_ribs" type="mesh" mesh="hat_ribs"></geom>
        <inertial pos="   -0.03     0.32        0" mass="34.2366" fullinertia="  1.4745   0.7555   1.4314        0        0        0"></inertial>
        <joint name="lumbar_extension" type="hinge" pos="0 0 0" axis="       0        0        1" limited="false" range=" -1.5708   1.5708" ref="0"></joint>
      </body>
    </body>
    <camera name="for_testing" pos="0 0 0" euler="0 0 0"></camera>
  </worldbody>
  <asset>
    <mesh name="sacrum" file="Geometry/sacrum.stl" scale="       1        1        1"></mesh>
    <mesh name="pelvis" file="Geometry/pelvis.stl" scale="       1        1        1"></mesh>
    <mesh name="l_pelvis" file="Geometry/l_pelvis.stl" scale="       1        1        1"></mesh>
    <mesh name="femur" file="Geometry/femur.stl" scale="       1        1        1"></mesh>
    <mesh name="tibia" file="Geometry/tibia.stl" scale="       1        1        1"></mesh>
    <mesh name="fibula" file="Geometry/fibula.stl" scale="       1        1        1"></mesh>
    <mesh name="talus" file="Geometry/talus.stl" scale="       1        1        1"></mesh>
    <mesh name="foot" file="Geometry/foot.stl" scale="       1        1        1"></mesh>
    <mesh name="bofoot" file="Geometry/bofoot.stl" scale="       1        1        1"></mesh>
    <mesh name="l_femur" file="Geometry/l_femur.stl" scale="       1        1        1"></mesh>
    <mesh name="l_tibia" file="Geometry/l_tibia.stl" scale="       1        1        1"></mesh>
    <mesh name="l_fibula" file="Geometry/l_fibula.stl" scale="       1        1        1"></mesh>
    <mesh name="l_talus" file="Geometry/l_talus.stl" scale="       1        1        1"></mesh>
    <mesh name="l_foot" file="Geometry/l_foot.stl" scale="       1        1        1"></mesh>
    <mesh name="l_bofoot" file="Geometry/l_bofoot.stl" scale="       1        1        1"></mesh>
    <mesh name="hat_spine" file="Geometry/hat_spine.stl" scale="       1        1        1"></mesh>
    <mesh name="hat_jaw" file="Geometry/hat_jaw.stl" scale="       1        1        1"></mesh>
    <mesh name="hat_skull" file="Geometry/hat_skull.stl" scale="       1        1        1"></mesh>
    <mesh name="hat_ribs" file="Geometry/hat_ribs.stl" scale="       1        1        1"></mesh>
    <texture name="texplane" type="2d" builtin="checker" rgb1=".2 .3 .4" rgb2=".1 0.15 0.2" width="100" height="100"></texture>
    <texture name="texgeom" type="cube" builtin="flat" mark="cross" width="127" height="1278" rgb1="0.8 0.6 0.4" rgb2="0.8 0.6 0.4" markrgb="1 1 1" random="0.01"></texture>
    <material name="MatPlane" reflectance="0.5" texture="texplane" texrepeat="1 1" texuniform="true"></material>
    <material name="geom" texture="texgeom" texuniform="true"></material>
  </asset>
  <tendon>
    <spatial name="hamstrings_r_tendon" springlength="0.326">
      <site site="bifemlh_r-P1"></site>
      <site site="bifemlh_r-P2"></site>
      <site site="bifemlh_r-P3"></site>
    </spatial>
    <spatial name="bifemsh_r_tendon" springlength="0.089">
      <site site="bifemsh_r-P1"></site>
      <site site="bifemsh_r-P2"></site>
      <site site="bifemsh_r-P3"></site>
    </spatial>
    <spatial name="glut_max_r_tendon" springlength="0.0733">
      <site site="glut_max_r-P1"></site>
      <site site="glut_max_r-P2"></site>
      <site site="glut_max_r-P3"></site>
      <site site="glut_max_r-P4"></site>
    </spatial>
    <spatial name="iliopsoas_r_tendon" springlength="0.16">
      <site site="psoas_r-P1"></site>
      <site site="psoas_r-P2"></site>
      <site site="psoas_r-P4"></site>
      <site site="psoas_r-P5"></site>
    </spatial>
    <spatial name="rect_fem_r_tendon" springlength="0.31">
      <site site="rect_fem_r-P1"></site>
      <site site="rect_fem_r-P3"></site>
    </spatial>
    <spatial name="vasti_r_tendon" springlength="0.116">
      <site site="vas_int_r-P1"></site>
      <site site="vas_int_r-P2"></site>
      <site site="vas_int_r-P4"></site>
    </spatial>
    <spatial name="gastroc_r_tendon" springlength="0.36">
      <site site="med_gas_r-P1"></site>
      <site site="med_gas_r-P3"></site>
    </spatial>
    <spatial name="soleus_r_tendon" springlength="0.25">
      <site site="soleus_r-P1"></site>
      <site site="soleus_r-P2"></site>
    </spatial>
    <spatial name="tib_ant_r_tendon" springlength="0.223">
      <site site="tib_ant_r-P1"></site>
      <site site="tib_ant_r-P2"></site>
      <site site="tib_ant_r-P3"></site>
    </spatial>
    <spatial name="hamstrings_l_tendon" springlength="0.326">
      <site site="bifemlh_l-P1"></site>
      <site site="bifemlh_l-P2"></site>
      <site site="bifemlh_l-P3"></site>
    </spatial>
    <spatial name="bifemsh_l_tendon" springlength="0.089">
      <site site="bifemsh_l-P1"></site>
      <site site="bifemsh_l-P2"></site>
      <site site="bifemsh_l-P3"></site>
    </spatial>
    <spatial name="glut_max_l_tendon" springlength="0.0733">
      <site site="glut_max_l-P1"></site>
      <site site="glut_max_l-P2"></site>
      <site site="glut_max_l-P3"></site>
      <site site="glut_max_l-P4"></site>
    </spatial>
    <spatial name="iliopsoas_l_tendon" springlength="0.16">
      <site site="psoas_l-P1"></site>
      <site site="psoas_l-P2"></site>
      <site site="psoas_l-P4"></site>
      <site site="psoas_l-P5"></site>
    </spatial>
    <spatial name="rect_fem_l_tendon" springlength="0.31">
      <site site="rect_fem_l-P1"></site>
      <site site="rect_fem_l-P3"></site>
    </spatial>
    <spatial name="vasti_l_tendon" springlength="0.116">
      <site site="vas_int_l-P1"></site>
      <site site="vas_int_l-P2"></site>
      <site site="vas_int_l-P4"></site>
    </spatial>
    <spatial name="gastroc_l_tendon" springlength="0.36">
      <site site="med_gas_l-P1"></site>
      <site site="med_gas_l-P3"></site>
    </spatial>
    <spatial name="soleus_l_tendon" springlength="0.25">
      <site site="soleus_l-P1"></site>
      <site site="soleus_l-P2"></site>
    </spatial>
    <spatial name="tib_ant_l_tendon" springlength="0.223">
      <site site="tib_ant_l-P1"></site>
      <site site="tib_ant_l-P2"></site>
      <site site="tib_ant_l-P3"></site>
    </spatial>
  </tendon>
  <actuator>
    <muscle name="hamstrings_r" tendon="hamstrings_r_tendon" class="muscle" timeconst="    0.01     0.04" ctrllimited="true" ctrlrange="       0        1"></muscle>
    <muscle name="bifemsh_r" tendon="bifemsh_r_tendon" class="muscle" timeconst="    0.01     0.04" ctrllimited="true" ctrlrange="       0        1"></muscle>
    <muscle name="glut_max_r" tendon="glut_max_r_tendon" class="muscle" timeconst="    0.01     0.04" ctrllimited="true" ctrlrange="       0        1"></muscle>
    <muscle name="iliopsoas_r" tendon="iliopsoas_r_tendon" class="muscle" timeconst="    0.01     0.04" ctrllimited="true" ctrlrange="       0        1"></muscle>
    <muscle name="rect_fem_r" tendon="rect_fem_r_tendon" class="muscle" timeconst="    0.01     0.04" ctrllimited="true" ctrlrange="       0        1"></muscle>
    <muscle name="vasti_r" tendon="vasti_r_tendon" class="muscle" timeconst="    0.01     0.04" ctrllimited="true" ctrlrange="       0        1"></muscle>
    <muscle name="gastroc_r" tendon="gastroc_r_tendon" class="muscle" timeconst="    0.01     0.04" ctrllimited="true" ctrlrange="       0        1"></muscle>
    <muscle name="soleus_r" tendon="soleus_r_tendon" class="muscle" timeconst="    0.01     0.04" ctrllimited="true" ctrlrange="       0        1"></muscle>
    <muscle name="tib_ant_r" tendon="tib_ant_r_tendon" class="muscle" timeconst="    0.01     0.04" ctrllimited="true" ctrlrange="       0        1"></muscle>
    <muscle name="hamstrings_l" tendon="hamstrings_l_tendon" class="muscle" timeconst="    0.01     0.04" ctrllimited="true" ctrlrange="       0        1"></muscle>
    <muscle name="bifemsh_l" tendon="bifemsh_l_tendon" class="muscle" timeconst="    0.01     0.04" ctrllimited="true" ctrlrange="       0        1"></muscle>
    <muscle name="glut_max_l" tendon="glut_max_l_tendon" class="muscle" timeconst="    0.01     0.04" ctrllimited="true" ctrlrange="       0        1"></muscle>
    <muscle name="iliopsoas_l" tendon="iliopsoas_l_tendon" class="muscle" timeconst="    0.01     0.04" ctrllimited="true" ctrlrange="       0        1"></muscle>
    <muscle name="rect_fem_l" tendon="rect_fem_l_tendon" class="muscle" timeconst="    0.01     0.04" ctrllimited="true" ctrlrange="       0        1"></muscle>
    <muscle name="vasti_l" tendon="vasti_l_tendon" class="muscle" timeconst="    0.01     0.04" ctrllimited="true" ctrlrange="       0        1"></muscle>
    <muscle name="gastroc_l" tendon="gastroc_l_tendon" class="muscle" timeconst="    0.01     0.04" ctrllimited="true" ctrlrange="       0        1"></muscle>
    <muscle name="soleus_l" tendon="soleus_l_tendon" class="muscle" timeconst="    0.01     0.04" ctrllimited="true" ctrlrange="       0        1"></muscle>
    <muscle name="tib_ant_l" tendon="tib_ant_l_tendon" class="muscle" timeconst="    0.01     0.04" ctrllimited="true" ctrlrange="       0        1"></muscle>
  </actuator>
  <equality>
    <joint name="knee_angle_r_translation2_constraint" active="true" joint1="knee_angle_r_translation2" joint2="knee_angle_r" polycoef="-0.395713 0.00341345 -0.00558653 0.000669664 0.000567409" solimp="0.9999 0.9999 0.001 0.5 2"></joint>
    <joint name="knee_angle_r_translation1_constraint" active="true" joint1="knee_angle_r_translation1" joint2="knee_angle_r" polycoef="-0.00363925 -0.00626677 0.00280689 0.00134038 -0.000677624" solimp="0.9999 0.9999 0.001 0.5 2"></joint>
    <joint name="knee_angle_l_translation2_constraint" active="true" joint1="knee_angle_l_translation2" joint2="knee_angle_l" polycoef="-0.395713 0.00341345 -0.00558653 0.000669664 0.000567409" solimp="0.9999 0.9999 0.001 0.5 2"></joint>
    <joint name="knee_angle_l_translation1_constraint" active="true" joint1="knee_angle_l_translation1" joint2="knee_angle_l" polycoef="-0.00363925 -0.00626677 0.00280689 0.00134038 -0.000677624" solimp="0.9999 0.9999 0.001 0.5 2"></joint>
    <weld name="origin_to_worldbody" body1="pelvis" active="false"></weld>
  </equality>
</mujoco>