<mujoco model="arm26">
  <compiler inertiafromgeom="auto" angle="radian" balanceinertia="true" boundmass="0.001" boundinertia="0.001">
    <lengthrange inttotal="500" />
  </compiler>
  <default>
    <joint limited="true" damping="0.5" armature="0.01" stiffness="0" />
    <geom contype="1" conaffinity="1" condim="3" rgba="0.8 0.6 .4 1" margin="0.001" solref=".02 1" solimp=".8 .8 .01" material="geom" />
    <default class="motor">
      <motor gear="20" />
    </default>
  </default>
  <option timestep="0.002">
    <flag energy="enable" />
  </option>
  <size njmax="1000" nconmax="400" nuser_jnt="1" />
  <visual>
    <map fogstart="3" fogend="5" force="0.1" />
    <quality shadowsize="2048" />
  </visual>
  <worldbody>
    <geom name="floor" pos="0 0 0" size="10 10 0.125" type="plane" material="MatPlane" condim="3" />
    <body name="r_humerus" pos="-0.017545    -0.17   -0.007" quat="0.7071067811865475 0.7071067811865475 0.0 0.0">
      <light mode="trackcom" directional="false" diffuse=".8 .8 .8" specular="0.3 0.3 0.3" pos="0 0 4.0" dir="0 0 -1" />
      <geom name="arm_r_humerus" type="mesh" mesh="arm_r_humerus" />
      <inertial pos="       0 -0.180496        0" mass="1.864572" fullinertia=" 0.01481 0.004551 0.013193        0        0        0" />
      <joint name="r_shoulder_elev" type="hinge" pos="0 0 0" axis="-0.058898   0.0023 0.998261" limited="false" range=" -1.5708  3.14159" ref="0" armature="0" damping="0" stiffness="0" />
      <body name="r_ulna_radius_hand" pos="  0.0061  -0.2904  -0.0123" quat="1.0 0.0 0.0 0.0">
        <geom name="arm_r_ulna" type="mesh" mesh="arm_r_ulna" />
        <geom name="arm_r_radius" type="mesh" mesh="arm_r_radius" />
        <geom name="arm_r_lunate" type="mesh" mesh="arm_r_lunate" />
        <geom name="arm_r_scaphoid" type="mesh" mesh="arm_r_scaphoid" />
        <geom name="arm_r_pisiform" type="mesh" mesh="arm_r_pisiform" />
        <geom name="arm_r_triquetrum" type="mesh" mesh="arm_r_triquetrum" />
        <geom name="arm_r_capitate" type="mesh" mesh="arm_r_capitate" />
        <geom name="arm_r_trapezium" type="mesh" mesh="arm_r_trapezium" />
        <geom name="arm_r_trapezoid" type="mesh" mesh="arm_r_trapezoid" />
        <geom name="arm_r_hamate" type="mesh" mesh="arm_r_hamate" />
        <geom name="arm_r_1mc" type="mesh" mesh="arm_r_1mc" />
        <geom name="arm_r_2mc" type="mesh" mesh="arm_r_2mc" />
        <geom name="arm_r_3mc" type="mesh" mesh="arm_r_3mc" />
        <geom name="arm_r_4mc" type="mesh" mesh="arm_r_4mc" />
        <geom name="arm_r_5mc" type="mesh" mesh="arm_r_5mc" />
        <geom name="arm_r_thumbprox" type="mesh" mesh="arm_r_thumbprox" />
        <geom name="arm_r_thumbdist" type="mesh" mesh="arm_r_thumbdist" />
        <geom name="arm_r_2proxph" type="mesh" mesh="arm_r_2proxph" />
        <geom name="arm_r_2midph" type="mesh" mesh="arm_r_2midph" />
        <geom name="arm_r_2distph" type="mesh" mesh="arm_r_2distph" />
        <geom name="arm_r_3proxph" type="mesh" mesh="arm_r_3proxph" />
        <geom name="arm_r_3midph" type="mesh" mesh="arm_r_3midph" />
        <geom name="arm_r_3distph" type="mesh" mesh="arm_r_3distph" />
        <geom name="arm_r_4proxph" type="mesh" mesh="arm_r_4proxph" />
        <geom name="arm_r_4midph" type="mesh" mesh="arm_r_4midph" />
        <geom name="arm_r_4distph" type="mesh" mesh="arm_r_4distph" />
        <geom name="arm_r_5proxph" type="mesh" mesh="arm_r_5proxph" />
        <geom name="arm_r_5midph" type="mesh" mesh="arm_r_5midph" />
        <geom name="arm_r_5distph" type="mesh" mesh="arm_r_5distph" />
        <inertial pos="       0 -0.181479        0" mass="1.534315" fullinertia="0.019281 0.001571 0.020062        0        0        0" />
        <joint name="r_elbow_flex" type="hinge" pos="0 0 0" axis="  0.0494   0.0366 0.998108" limited="false" range="       0  2.26893" ref="0" />
      </body>
    </body>
    <camera name="for_testing" pos="0 0 0" euler="0 0 0" />
  </worldbody>
  <asset>
    <mesh name="arm_r_humerus" file="Geometry/arm_r_humerus.stl" scale="       1        1        1" />
    <mesh name="arm_r_ulna" file="Geometry/arm_r_ulna.stl" scale="       1        1        1" />
    <mesh name="arm_r_radius" file="Geometry/arm_r_radius.stl" scale="       1        1        1" />
    <mesh name="arm_r_lunate" file="Geometry/arm_r_lunate.stl" scale="       1        1        1" />
    <mesh name="arm_r_scaphoid" file="Geometry/arm_r_scaphoid.stl" scale="       1        1        1" />
    <mesh name="arm_r_pisiform" file="Geometry/arm_r_pisiform.stl" scale="       1        1        1" />
    <mesh name="arm_r_triquetrum" file="Geometry/arm_r_triquetrum.stl" scale="       1        1        1" />
    <mesh name="arm_r_capitate" file="Geometry/arm_r_capitate.stl" scale="       1        1        1" />
    <mesh name="arm_r_trapezium" file="Geometry/arm_r_trapezium.stl" scale="       1        1        1" />
    <mesh name="arm_r_trapezoid" file="Geometry/arm_r_trapezoid.stl" scale="       1        1        1" />
    <mesh name="arm_r_hamate" file="Geometry/arm_r_hamate.stl" scale="       1        1        1" />
    <mesh name="arm_r_1mc" file="Geometry/arm_r_1mc.stl" scale="       1        1        1" />
    <mesh name="arm_r_2mc" file="Geometry/arm_r_2mc.stl" scale="       1        1        1" />
    <mesh name="arm_r_3mc" file="Geometry/arm_r_3mc.stl" scale="       1        1        1" />
    <mesh name="arm_r_4mc" file="Geometry/arm_r_4mc.stl" scale="       1        1        1" />
    <mesh name="arm_r_5mc" file="Geometry/arm_r_5mc.stl" scale="       1        1        1" />
    <mesh name="arm_r_thumbprox" file="Geometry/arm_r_thumbprox.stl" scale="       1        1        1" />
    <mesh name="arm_r_thumbdist" file="Geometry/arm_r_thumbdist.stl" scale="       1        1        1" />
    <mesh name="arm_r_2proxph" file="Geometry/arm_r_2proxph.stl" scale="       1        1        1" />
    <mesh name="arm_r_2midph" file="Geometry/arm_r_2midph.stl" scale="       1        1        1" />
    <mesh name="arm_r_2distph" file="Geometry/arm_r_2distph.stl" scale="       1        1        1" />
    <mesh name="arm_r_3proxph" file="Geometry/arm_r_3proxph.stl" scale="       1        1        1" />
    <mesh name="arm_r_3midph" file="Geometry/arm_r_3midph.stl" scale="       1        1        1" />
    <mesh name="arm_r_3distph" file="Geometry/arm_r_3distph.stl" scale="       1        1        1" />
    <mesh name="arm_r_4proxph" file="Geometry/arm_r_4proxph.stl" scale="       1        1        1" />
    <mesh name="arm_r_4midph" file="Geometry/arm_r_4midph.stl" scale="       1        1        1" />
    <mesh name="arm_r_4distph" file="Geometry/arm_r_4distph.stl" scale="       1        1        1" />
    <mesh name="arm_r_5proxph" file="Geometry/arm_r_5proxph.stl" scale="       1        1        1" />
    <mesh name="arm_r_5midph" file="Geometry/arm_r_5midph.stl" scale="       1        1        1" />
    <mesh name="arm_r_5distph" file="Geometry/arm_r_5distph.stl" scale="       1        1        1" />
    <texture name="texplane" type="2d" builtin="checker" rgb1=".2 .3 .4" rgb2=".1 0.15 0.2" width="100" height="100" />
    <texture name="texgeom" type="cube" builtin="flat" mark="cross" width="127" height="1278" rgb1="0.8 0.6 0.4" rgb2="0.8 0.6 0.4" markrgb="1 1 1" random="0.01" />
    <material name="MatPlane" reflectance="0.5" texture="texplane" texrepeat="1 1" texuniform="true" />
    <material name="geom" texture="texgeom" texuniform="true" />
  </asset>
  <actuator>
    <motor name="r_elbow_flex" joint="r_elbow_flex" class="motor" />
		<motor name="r_shoulder_elev" joint="r_shoulder_elev" class="motor" />
		</actuator>
  <equality>
    <weld name="origin_to_worldbody" body1="r_humerus" active="false" />
  </equality>
</mujoco>