<?xml version="1.0" encoding="utf-8"?>
<mujoco model="3DGaitModel2354">
  <compiler inertiafromgeom="auto" angle="radian" balanceinertia="true" boundmass="0.001" boundinertia="0.001">
    <lengthrange inttotal="500"></lengthrange>
  </compiler>
  <default>
    <joint limited="true" damping="0.5" armature="0.01" stiffness="0"></joint>
    <geom contype="1" conaffinity="1" condim="3" rgba="0.8 0.6 .4 1" margin="0.001" solref=".02 1" solimp=".8 .8 .01" material="geom"></geom>
    <site size="0.001"></site>
    <tendon width="0.001" rgba=".95 .3 .3 1" limited="false"></tendon>
    <default class="muscle">
      <muscle ctrllimited="true" ctrlrange="0 1" scale="400"></muscle>
    </default>
    <default class="motor">
      <motor gear="20"></motor>
    </default>
  </default>
  <option timestep="0.002">
    <flag energy="enable"></flag>
  </option>
  <size njmax="1000" nconmax="400" nuser_jnt="1"></size>
  <visual>
    <map fogstart="3" fogend="5" force="0.1"></map>
    <quality shadowsize="2048"></quality>
  </visual>
  <worldbody>
    <geom name="floor" pos="0 0 0" size="10 10 0.125" type="plane" material="MatPlane" condim="3"></geom>
    <body name="pelvis" pos="       0        0        0" quat="0.7071067811865475 0.7071067811865475 0.0 0.0">
      <light mode="trackcom" directional="false" diffuse=".8 .8 .8" specular="0.3 0.3 0.3" pos="0 0 4.0" dir="0 0 -1"></light>
      <geom name="sacrum" type="mesh" mesh="sacrum"></geom>
      <geom name="pelvis" type="mesh" mesh="pelvis"></geom>
      <geom name="l_pelvis" type="mesh" mesh="l_pelvis"></geom>
      <inertial pos=" -0.0707        0        0" mass="11.777" fullinertia="  0.1028   0.0871   0.0579        0        0        0"></inertial>
      <site name="glut_med1_r-P1" pos="-0.0408 0.0304 0.1209"></site>
      <site name="glut_med2_r-P1" pos="-0.0855 0.0445 0.0766"></site>
      <site name="glut_med3_r-P1" pos="-0.1223 0.0105 0.0648"></site>
      <site name="bifemlh_r-P1" pos="-0.12596 -0.10257 0.06944"></site>
      <site name="sar_r-P1" pos="-0.0153 -0.0013 0.1242"></site>
      <site name="add_mag2_r-P1" pos="-0.0831 -0.1192 0.0308"></site>
      <site name="tfl_r-P1" pos="-0.0311 0.0214 0.1241"></site>
      <site name="pect_r-P1" pos="-0.0431 -0.0768 0.0451"></site>
      <site name="grac_r-P1" pos="-0.07401 -0.1187 0.02794"></site>
      <site name="glut_max1_r-P1" pos="-0.1195 0.0612 0.07"></site>
      <site name="glut_max1_r-P2" pos="-0.1291 0.0012 0.0886"></site>
      <site name="glut_max2_r-P1" pos="-0.1349 0.0176 0.0563"></site>
      <site name="glut_max2_r-P2" pos="-0.1376 -0.052 0.0914"></site>
      <site name="glut_max3_r-P1" pos="-0.1556 -0.0314 0.0058"></site>
      <site name="glut_max3_r-P2" pos="-0.1529 -0.1052 0.0403"></site>
      <site name="iliacus_r-P1" pos="-0.0674 0.0365 0.0854"></site>
      <site name="iliacus_r-P2" pos="-0.0258 -0.055 0.0811"></site>
      <site name="psoas_r-P1" pos="-0.0647 0.0887 0.0289"></site>
      <site name="psoas_r-P2" pos="-0.0238 -0.057 0.0759"></site>
      <site name="quad_fem_r-P1" pos="-0.1143 -0.1151 0.052"></site>
      <site name="gem_r-P1" pos="-0.1133 -0.082 0.0714"></site>
      <site name="peri_r-P1" pos="-0.1396 0.0003 0.0235"></site>
      <site name="peri_r-P2" pos="-0.1193 -0.0276 0.0657"></site>
      <site name="rect_fem_r-P1" pos="-0.0295 -0.0311 0.0968"></site>
      <site name="glut_med1_l-P1" pos="-0.0408 0.0304 -0.1209"></site>
      <site name="glut_med2_l-P1" pos="-0.0855 0.0445 -0.0766"></site>
      <site name="glut_med3_l-P1" pos="-0.1223 0.0105 -0.0648"></site>
      <site name="bifemlh_l-P1" pos="-0.12596 -0.10257 -0.06944"></site>
      <site name="sar_l-P1" pos="-0.0153 -0.0013 -0.1242"></site>
      <site name="add_mag2_l-P1" pos="-0.0831 -0.1192 -0.0308"></site>
      <site name="tfl_l-P1" pos="-0.0311 0.0214 -0.1241"></site>
      <site name="pect_l-P1" pos="-0.0431 -0.0768 -0.0451"></site>
      <site name="grac_l-P1" pos="-0.07401 -0.1187 -0.02794"></site>
      <site name="glut_max1_l-P1" pos="-0.1195 0.0612 -0.07"></site>
      <site name="glut_max1_l-P2" pos="-0.1291 0.0012 -0.0886"></site>
      <site name="glut_max2_l-P1" pos="-0.1349 0.0176 -0.0563"></site>
      <site name="glut_max2_l-P2" pos="-0.1376 -0.052 -0.0914"></site>
      <site name="glut_max3_l-P1" pos="-0.1556 -0.0314 -0.0058"></site>
      <site name="glut_max3_l-P2" pos="-0.1529 -0.1052 -0.0403"></site>
      <site name="iliacus_l-P1" pos="-0.0674 0.0365 -0.0854"></site>
      <site name="iliacus_l-P2" pos="-0.0258 -0.055 -0.0811"></site>
      <site name="psoas_l-P1" pos="-0.0647 0.0887 -0.0289"></site>
      <site name="psoas_l-P2" pos="-0.0238 -0.057 -0.0759"></site>
      <site name="quad_fem_l-P1" pos="-0.1143 -0.1151 -0.052"></site>
      <site name="gem_l-P1" pos="-0.1133 -0.082 -0.0714"></site>
      <site name="peri_l-P1" pos="-0.1396 0.0003 -0.0235"></site>
      <site name="peri_l-P2" pos="-0.1193 -0.0276 -0.0657"></site>
      <site name="rect_fem_l-P1" pos="-0.0295 -0.0311 -0.0968"></site>
      <site name="ercspn_r-P1" pos="-0.14 0.0439 0.0436"></site>
      <site name="ercspn_l-P1" pos="-0.14 0.0439 -0.0436"></site>
      <site name="intobl_r-P1" pos="-0.04 0.07 0.1157"></site>
      <site name="intobl_l-P1" pos="-0.04 0.07 -0.1157"></site>
      <site name="extobl_r-P1" pos="-0.03 -0.0636 0.01"></site>
      <site name="extobl_l-P1" pos="-0.03 -0.0636 -0.01"></site>
      <joint name="pelvis_tz" type="slide" pos="0 0 0" axis="       0        0        1" limited="false" range="      -3        3" ref="0" armature="0" damping="0" stiffness="0"></joint>
      <joint name="pelvis_ty" type="slide" pos="0 0 0" axis="       0        1        0" limited="false" range="      -1        2" ref="0" armature="0" damping="0" stiffness="0"></joint>
      <joint name="pelvis_tx" type="slide" pos="0 0 0" axis="       1        0        0" limited="false" range="      -5        5" ref="0" armature="0" damping="0" stiffness="0"></joint>
      <joint name="pelvis_tilt" type="hinge" pos="0 0 0" axis="       0        0        1" limited="false" range=" -1.5708   1.5708" ref="0" armature="0" damping="0" stiffness="0"></joint>
      <joint name="pelvis_list" type="hinge" pos="0 0 0" axis="       1        0        0" limited="false" range=" -1.5708   1.5708" ref="0" armature="0" damping="0" stiffness="0"></joint>
      <joint name="pelvis_rotation" type="hinge" pos="0 0 0" axis="       0        1        0" limited="false" range=" -1.5708   1.5708" ref="0" armature="0" damping="0" stiffness="0"></joint>
      <body name="femur_r" pos=" -0.0707  -0.0661   0.0835" quat="1.0 0.0 0.0 0.0">
        <geom name="femur" type="mesh" mesh="femur"></geom>
        <inertial pos="       0    -0.17        0" mass="9.3014" fullinertia="  0.1339   0.0351   0.1412        0        0        0"></inertial>
        <site name="glut_med1_r-P2" pos="-0.0218 -0.0117 0.0555"></site>
        <site name="glut_med2_r-P2" pos="-0.0258 -0.0058 0.0527"></site>
        <site name="glut_med3_r-P2" pos="-0.0309 -0.0047 0.0518"></site>
        <site name="bifemsh_r-P1" pos="0.005 -0.2111 0.0234"></site>
        <site name="sar_r-P2" pos="-0.003 -0.3568 -0.0421"></site>
        <site name="add_mag2_r-P2" pos="0.0054 -0.2285 0.0227"></site>
        <site name="tfl_r-P2" pos="0.0294 -0.0995 0.0597"></site>
        <site name="tfl_r-P3" pos="0.0054 -0.4049 0.0357"></site>
        <site name="pect_r-P2" pos="-0.0122 -0.0822 0.0253"></site>
        <site name="glut_max1_r-P3" pos="-0.0457 -0.0248 0.0392"></site>
        <site name="glut_max1_r-P4" pos="-0.0277 -0.0566 0.047"></site>
        <site name="glut_max2_r-P3" pos="-0.0426 -0.053 0.0293"></site>
        <site name="glut_max2_r-P4" pos="-0.0156 -0.1016 0.0419"></site>
        <site name="glut_max3_r-P3" pos="-0.0299 -0.1041 0.0135"></site>
        <site name="glut_max3_r-P4" pos="-0.006 -0.1419 0.0411"></site>
        <site name="iliacus_r-P4" pos="0.0017 -0.0543 0.0057"></site>
        <site name="iliacus_r-P5" pos="-0.0193 -0.0621 0.0129"></site>
        <site name="psoas_r-P4" pos="0.0016 -0.0507 0.0038"></site>
        <site name="psoas_r-P5" pos="-0.0188 -0.0597 0.0104"></site>
        <site name="quad_fem_r-P2" pos="-0.0381 -0.0359 0.0366"></site>
        <site name="gem_r-P2" pos="-0.0142 -0.0033 0.0443"></site>
        <site name="peri_r-P3" pos="-0.0148 -0.0036 0.0437"></site>
        <site name="vas_int_r-P1" pos="0.029 -0.1924 0.031"></site>
        <site name="vas_int_r-P2" pos="0.0335 -0.2084 0.0285"></site>
        <site name="med_gas_r-P1" pos="-0.019 -0.3929 -0.0235"></site>
        <joint name="hip_flexion_r" type="hinge" pos="0 0 0" axis="       0        0        1" limited="false" range=" -2.0944   2.0944" ref="0"></joint>
        <joint name="hip_adduction_r" type="hinge" pos="0 0 0" axis="       1        0        0" limited="false" range=" -2.0944   2.0944" ref="0"></joint>
        <joint name="hip_rotation_r" type="hinge" pos="0 0 0" axis="       0        1        0" limited="false" range=" -2.0944   2.0944" ref="0"></joint>
        <body name="tibia_r" pos="       0        0        0" quat="1.0 0.0 0.0 0.0">
          <geom name="tibia" type="mesh" mesh="tibia"></geom>
          <geom name="fibula" type="mesh" mesh="fibula"></geom>
          <inertial pos="       0  -0.1867        0" mass="3.7075" fullinertia="  0.0504   0.0051   0.0511        0        0        0"></inertial>
          <site name="bifemlh_r-P2" pos="-0.0301 -0.036 0.02943"></site>
          <site name="bifemlh_r-P3" pos="-0.0234 -0.0563 0.0343"></site>
          <site name="bifemsh_r-P2" pos="-0.0301 -0.036 0.02943"></site>
          <site name="bifemsh_r-P3" pos="-0.0234 -0.0563 0.0343"></site>
          <site name="sar_r-P3" pos="-0.0056 -0.0419 -0.0399"></site>
          <site name="sar_r-P4" pos="0.006 -0.0589 -0.0383"></site>
          <site name="sar_r-P5" pos="0.0243 -0.084 -0.0252"></site>
          <site name="tfl_r-P4" pos="0.006 -0.0487 0.0297"></site>
          <site name="grac_r-P3" pos="-0.01943 -0.05153 -0.0358"></site>
          <site name="grac_r-P4" pos="0.006 -0.0836 -0.0228"></site>
          <site name="rect_fem_r-P3" pos="0.0780827 -0.0123631   0.0014"></site>
          <site name="vas_int_r-P4" pos="0.0785259 -0.00619903   0.0018"></site>
          <site name="soleus_r-P1" pos="-0.0024 -0.1533 0.0071"></site>
          <site name="tib_post_r-P1" pos="-0.0094 -0.1348 0.0019"></site>
          <site name="tib_post_r-P2" pos="-0.0144 -0.4051 -0.0229"></site>
          <site name="tib_ant_r-P1" pos="0.0179 -0.1624 0.0115"></site>
          <site name="tib_ant_r-P2" pos="0.0329 -0.3951 -0.0177"></site>
          <joint name="knee_angle_r_translation2" type="slide" pos="0 0 0" axis="       0        1        0" limited="true" range="-0.422602 -0.395309" ref="0"></joint>
          <joint name="knee_angle_r_translation1" type="slide" pos="0 0 0" axis="       1        0        0" limited="true" range="-0.00591791 0.00435888" ref="0"></joint>
          <joint name="knee_angle_r" type="hinge" pos="0 0 0" axis="       0        0        1" limited="false" range=" -2.0944 0.174533" ref="0"></joint>
          <body name="talus_r" pos="       0    -0.43        0" quat="1.0 0.0 0.0 0.0">
            <geom name="talus" type="mesh" mesh="talus"></geom>
            <inertial pos="       0        0        0" mass="0.1" fullinertia="   0.001    0.001    0.001        0        0        0"></inertial>
            <joint name="ankle_angle_r" type="hinge" pos="0 0 0" axis="-0.105014 -0.174022 0.979126" limited="false" range=" -1.5708   1.5708" ref="0"></joint>
            <body name="calcn_r" pos="-0.04877 -0.04195  0.00792" quat="1.0 0.0 0.0 0.0">
              <geom name="foot" type="mesh" mesh="foot"></geom>
              <inertial pos="     0.1     0.03        0" mass="1.25" fullinertia="  0.0014   0.0039   0.0041        0        0        0"></inertial>
              <site name="med_gas_r-P3" pos="0 0.031 -0.0053"></site>
              <site name="soleus_r-P2" pos="0 0.031 -0.0053"></site>
              <site name="tib_post_r-P3" pos="0.0417 0.0334 -0.0286"></site>
              <site name="tib_post_r-P4" pos="0.0772 0.0159 -0.0281"></site>
              <site name="tib_ant_r-P3" pos="0.1166 0.0178 -0.0305"></site>
              <joint name="subtalar_angle_r" type="hinge" pos="0 0 0" axis=" 0.78718 0.604747 -0.120949" limited="false" range=" -1.5708   1.5708" ref="0"></joint>
              <body name="toes_r" pos="  0.1788   -0.002  0.00108" quat="1.0 0.0 0.0 0.0">
                <geom name="bofoot" type="mesh" mesh="bofoot"></geom>
                <inertial pos="  0.0346    0.006  -0.0175" mass="0.2166" fullinertia="  0.0001   0.0002   0.0001        0        0        0"></inertial>
                <joint name="mtp_angle_r" type="hinge" pos="0 0 0" axis="-0.580954        0 0.813936" limited="false" range=" -1.5708   1.5708" ref="0"></joint>
              </body>
            </body>
          </body>
        </body>
      </body>
      <body name="femur_l" pos=" -0.0707  -0.0661  -0.0835" quat="1.0 0.0 0.0 0.0">
        <geom name="l_femur" type="mesh" mesh="l_femur"></geom>
        <inertial pos="       0    -0.17        0" mass="9.3014" fullinertia="  0.1339   0.0351   0.1412        0        0        0"></inertial>
        <site name="glut_med1_l-P2" pos="-0.0218 -0.0117 -0.0555"></site>
        <site name="glut_med2_l-P2" pos="-0.0258 -0.0058 -0.0527"></site>
        <site name="glut_med3_l-P2" pos="-0.0309 -0.0047 -0.0518"></site>
        <site name="bifemsh_l-P1" pos="0.005 -0.2111 -0.0234"></site>
        <site name="sar_l-P2" pos="-0.003 -0.3568 0.0421"></site>
        <site name="add_mag2_l-P2" pos="0.0054 -0.2285 -0.0227"></site>
        <site name="tfl_l-P2" pos="0.0294 -0.0995 -0.0597"></site>
        <site name="tfl_l-P3" pos="0.0054 -0.4049 -0.0357"></site>
        <site name="pect_l-P2" pos="-0.0122 -0.0822 -0.0253"></site>
        <site name="glut_max1_l-P3" pos="-0.0457 -0.0248 -0.0392"></site>
        <site name="glut_max1_l-P4" pos="-0.0277 -0.0566 -0.047"></site>
        <site name="glut_max2_l-P3" pos="-0.0426 -0.053 -0.0293"></site>
        <site name="glut_max2_l-P4" pos="-0.0156 -0.1016 -0.0419"></site>
        <site name="glut_max3_l-P3" pos="-0.0299 -0.1041 -0.0135"></site>
        <site name="glut_max3_l-P4" pos="-0.006 -0.1419 -0.0411"></site>
        <site name="iliacus_l-P4" pos="0.0017 -0.0543 -0.0057"></site>
        <site name="iliacus_l-P5" pos="-0.0193 -0.0621 -0.0129"></site>
        <site name="psoas_l-P4" pos="0.0016 -0.0507 -0.0038"></site>
        <site name="psoas_l-P5" pos="-0.0188 -0.0597 -0.0104"></site>
        <site name="quad_fem_l-P2" pos="-0.0381 -0.0359 -0.0366"></site>
        <site name="gem_l-P2" pos="-0.0142 -0.0033 -0.0443"></site>
        <site name="peri_l-P3" pos="-0.0148 -0.0036 -0.0437"></site>
        <site name="vas_int_l-P1" pos="0.029 -0.1924 -0.031"></site>
        <site name="vas_int_l-P2" pos="0.0335 -0.2084 -0.0285"></site>
        <site name="med_gas_l-P1" pos="-0.019 -0.3929 0.0235"></site>
        <joint name="hip_flexion_l" type="hinge" pos="0 0 0" axis="       0        0        1" limited="false" range=" -2.0944   2.0944" ref="0"></joint>
        <joint name="hip_adduction_l" type="hinge" pos="0 0 0" axis="      -1        0        0" limited="false" range=" -2.0944   2.0944" ref="0"></joint>
        <joint name="hip_rotation_l" type="hinge" pos="0 0 0" axis="       0       -1        0" limited="false" range=" -2.0944   2.0944" ref="0"></joint>
        <body name="tibia_l" pos="       0        0        0" quat="1.0 0.0 0.0 0.0">
          <geom name="l_tibia" type="mesh" mesh="l_tibia"></geom>
          <geom name="l_fibula" type="mesh" mesh="l_fibula"></geom>
          <inertial pos="       0  -0.1867        0" mass="3.7075" fullinertia="  0.0504   0.0051   0.0511        0        0        0"></inertial>
          <site name="bifemlh_l-P2" pos="-0.0301 -0.036 -0.02943"></site>
          <site name="bifemlh_l-P3" pos="-0.0234 -0.0563 -0.0343"></site>
          <site name="bifemsh_l-P2" pos="-0.0301 -0.036 -0.02943"></site>
          <site name="bifemsh_l-P3" pos="-0.0234 -0.0563 -0.0343"></site>
          <site name="sar_l-P3" pos="-0.0056 -0.0419 0.0399"></site>
          <site name="sar_l-P4" pos="0.006 -0.0589 0.0383"></site>
          <site name="sar_l-P5" pos="0.0243 -0.084 0.0252"></site>
          <site name="tfl_l-P4" pos="0.006 -0.0487 -0.0297"></site>
          <site name="grac_l-P3" pos="-0.01943 -0.05153 0.0358"></site>
          <site name="grac_l-P4" pos="0.006 -0.0836 0.0228"></site>
          <site name="rect_fem_l-P3" pos="0.0780827 -0.0123631  -0.0014"></site>
          <site name="vas_int_l-P4" pos="0.0785259 -0.00619903  -0.0018"></site>
          <site name="soleus_l-P1" pos="-0.0024 -0.1533 -0.0071"></site>
          <site name="tib_post_l-P1" pos="-0.0094 -0.1348 -0.0019"></site>
          <site name="tib_post_l-P2" pos="-0.0144 -0.4051 0.0229"></site>
          <site name="tib_ant_l-P1" pos="0.0179 -0.1624 -0.0115"></site>
          <site name="tib_ant_l-P2" pos="0.0329 -0.3951 0.0177"></site>
          <joint name="knee_angle_l_translation2" type="slide" pos="0 0 0" axis="       0        1        0" limited="true" range="-0.422602 -0.395309" ref="0"></joint>
          <joint name="knee_angle_l_translation1" type="slide" pos="0 0 0" axis="       1        0        0" limited="true" range="-0.00591791 0.00435888" ref="0"></joint>
          <joint name="knee_angle_l" type="hinge" pos="0 0 0" axis="       0        0        1" limited="false" range=" -2.0944 0.174533" ref="0"></joint>
          <body name="talus_l" pos="       0    -0.43        0" quat="1.0 0.0 0.0 0.0">
            <geom name="l_talus" type="mesh" mesh="l_talus"></geom>
            <inertial pos="       0        0        0" mass="0.1" fullinertia="   0.001    0.001    0.001        0        0        0"></inertial>
            <joint name="ankle_angle_l" type="hinge" pos="0 0 0" axis="0.105014 0.174022 0.979126" limited="false" range=" -1.0472   1.0472" ref="0"></joint>
            <body name="calcn_l" pos="-0.04877 -0.04195 -0.00792" quat="1.0 0.0 0.0 0.0">
              <geom name="l_foot" type="mesh" mesh="l_foot"></geom>
              <inertial pos="     0.1     0.03        0" mass="1.25" fullinertia="  0.0014   0.0039   0.0041        0        0        0"></inertial>
              <site name="med_gas_l-P3" pos="0 0.031 0.0053"></site>
              <site name="soleus_l-P2" pos="0 0.031 0.0053"></site>
              <site name="tib_post_l-P3" pos="0.0417 0.0334 0.0286"></site>
              <site name="tib_post_l-P4" pos="0.0772 0.0159 0.0281"></site>
              <site name="tib_ant_l-P3" pos="0.1166 0.0178 0.0305"></site>
              <joint name="subtalar_angle_l" type="hinge" pos="0 0 0" axis="-0.78718 -0.604747 -0.120949" limited="false" range=" -1.5708   1.5708" ref="0"></joint>
              <body name="toes_l" pos="  0.1788   -0.002 -0.00108" quat="1.0 0.0 0.0 0.0">
                <geom name="l_bofoot" type="mesh" mesh="l_bofoot"></geom>
                <inertial pos="  0.0346    0.006   0.0175" mass="0.2166" fullinertia="  0.0001   0.0002   0.0001        0        0        0"></inertial>
                <joint name="mtp_angle_l" type="hinge" pos="0 0 0" axis="0.580954        0 0.813936" limited="false" range=" -1.0472   1.0472" ref="0"></joint>
              </body>
            </body>
          </body>
        </body>
      </body>
      <body name="torso" pos=" -0.1007   0.0815        0" quat="1.0 0.0 0.0 0.0">
        <geom name="hat_spine" type="mesh" mesh="hat_spine"></geom>
        <geom name="hat_jaw" type="mesh" mesh="hat_jaw"></geom>
        <geom name="hat_skull" type="mesh" mesh="hat_skull"></geom>
        <geom name="hat_ribs" type="mesh" mesh="hat_ribs"></geom>
        <inertial pos="   -0.03     0.32        0" mass="34.2366" fullinertia="  1.4745   0.7555   1.4314        0        0        0"></inertial>
        <site name="ercspn_r-P2" pos="-0.055 0.11 0.0241"></site>
        <site name="ercspn_l-P2" pos="-0.055 0.11 -0.0241"></site>
        <site name="intobl_r-P2" pos="0.07 0.16 0.015"></site>
        <site name="intobl_l-P2" pos="0.07 0.16 -0.015"></site>
        <site name="extobl_r-P2" pos="0.065 0.11 0.11"></site>
        <site name="extobl_l-P2" pos="0.065 0.11 -0.11"></site>
        <joint name="lumbar_extension" type="hinge" pos="0 0 0" axis="       0        0        1" limited="false" range=" -1.5708   1.5708" ref="0"></joint>
        <joint name="lumbar_bending" type="hinge" pos="0 0 0" axis="       1        0        0" limited="false" range=" -1.5708   1.5708" ref="0"></joint>
        <joint name="lumbar_rotation" type="hinge" pos="0 0 0" axis="       0        1        0" limited="false" range=" -1.5708   1.5708" ref="0"></joint>
      </body>
    </body>
    <camera name="for_testing" pos="0 0 0" euler="0 0 0"></camera>
  </worldbody>
  <asset>
    <mesh name="sacrum" file="Geometry/sacrum.stl" scale="       1        1        1"></mesh>
    <mesh name="pelvis" file="Geometry/pelvis.stl" scale="       1        1        1"></mesh>
    <mesh name="l_pelvis" file="Geometry/l_pelvis.stl" scale="       1        1        1"></mesh>
    <mesh name="femur" file="Geometry/femur.stl" scale="       1        1        1"></mesh>
    <mesh name="tibia" file="Geometry/tibia.stl" scale="       1        1        1"></mesh>
    <mesh name="fibula" file="Geometry/fibula.stl" scale="       1        1        1"></mesh>
    <mesh name="talus" file="Geometry/talus.stl" scale="       1        1        1"></mesh>
    <mesh name="foot" file="Geometry/foot.stl" scale="       1        1        1"></mesh>
    <mesh name="bofoot" file="Geometry/bofoot.stl" scale="       1        1        1"></mesh>
    <mesh name="l_femur" file="Geometry/l_femur.stl" scale="       1        1        1"></mesh>
    <mesh name="l_tibia" file="Geometry/l_tibia.stl" scale="       1        1        1"></mesh>
    <mesh name="l_fibula" file="Geometry/l_fibula.stl" scale="       1        1        1"></mesh>
    <mesh name="l_talus" file="Geometry/l_talus.stl" scale="       1        1        1"></mesh>
    <mesh name="l_foot" file="Geometry/l_foot.stl" scale="       1        1        1"></mesh>
    <mesh name="l_bofoot" file="Geometry/l_bofoot.stl" scale="       1        1        1"></mesh>
    <mesh name="hat_spine" file="Geometry/hat_spine.stl" scale="       1        1        1"></mesh>
    <mesh name="hat_jaw" file="Geometry/hat_jaw.stl" scale="       1        1        1"></mesh>
    <mesh name="hat_skull" file="Geometry/hat_skull.stl" scale="       1        1        1"></mesh>
    <mesh name="hat_ribs" file="Geometry/hat_ribs.stl" scale="       1        1        1"></mesh>
    <texture name="texplane" type="2d" builtin="checker" rgb1=".2 .3 .4" rgb2=".1 0.15 0.2" width="100" height="100"></texture>
    <texture name="texgeom" type="cube" builtin="flat" mark="cross" width="127" height="1278" rgb1="0.8 0.6 0.4" rgb2="0.8 0.6 0.4" markrgb="1 1 1" random="0.01"></texture>
    <material name="MatPlane" reflectance="0.5" texture="texplane" texrepeat="1 1" texuniform="true"></material>
    <material name="geom" texture="texgeom" texuniform="true"></material>
  </asset>
  <tendon>
    <spatial name="glut_med1_r_tendon" springlength="0.078">
      <site site="glut_med1_r-P1"></site>
      <site site="glut_med1_r-P2"></site>
    </spatial>
    <spatial name="glut_med2_r_tendon" springlength="0.053">
      <site site="glut_med2_r-P1"></site>
      <site site="glut_med2_r-P2"></site>
    </spatial>
    <spatial name="glut_med3_r_tendon" springlength="0.053">
      <site site="glut_med3_r-P1"></site>
      <site site="glut_med3_r-P2"></site>
    </spatial>
    <spatial name="bifemlh_r_tendon" springlength="0.326">
      <site site="bifemlh_r-P1"></site>
      <site site="bifemlh_r-P2"></site>
      <site site="bifemlh_r-P3"></site>
    </spatial>
    <spatial name="bifemsh_r_tendon" springlength="0.089">
      <site site="bifemsh_r-P1"></site>
      <site site="bifemsh_r-P2"></site>
      <site site="bifemsh_r-P3"></site>
    </spatial>
    <spatial name="sar_r_tendon" springlength="0.1">
      <site site="sar_r-P1"></site>
      <site site="sar_r-P2"></site>
      <site site="sar_r-P3"></site>
      <site site="sar_r-P4"></site>
      <site site="sar_r-P5"></site>
    </spatial>
    <spatial name="add_mag2_r_tendon" springlength="0.12">
      <site site="add_mag2_r-P1"></site>
      <site site="add_mag2_r-P2"></site>
    </spatial>
    <spatial name="tfl_r_tendon" springlength="0.425">
      <site site="tfl_r-P1"></site>
      <site site="tfl_r-P2"></site>
      <site site="tfl_r-P3"></site>
      <site site="tfl_r-P4"></site>
    </spatial>
    <spatial name="pect_r_tendon" springlength="0.033">
      <site site="pect_r-P1"></site>
      <site site="pect_r-P2"></site>
    </spatial>
    <spatial name="grac_r_tendon" springlength="0.126">
      <site site="grac_r-P1"></site>
      <site site="grac_r-P3"></site>
      <site site="grac_r-P4"></site>
    </spatial>
    <spatial name="glut_max1_r_tendon" springlength="0.125">
      <site site="glut_max1_r-P1"></site>
      <site site="glut_max1_r-P2"></site>
      <site site="glut_max1_r-P3"></site>
      <site site="glut_max1_r-P4"></site>
    </spatial>
    <spatial name="glut_max2_r_tendon" springlength="0.127">
      <site site="glut_max2_r-P1"></site>
      <site site="glut_max2_r-P2"></site>
      <site site="glut_max2_r-P3"></site>
      <site site="glut_max2_r-P4"></site>
    </spatial>
    <spatial name="glut_max3_r_tendon" springlength="0.145">
      <site site="glut_max3_r-P1"></site>
      <site site="glut_max3_r-P2"></site>
      <site site="glut_max3_r-P3"></site>
      <site site="glut_max3_r-P4"></site>
    </spatial>
    <spatial name="iliacus_r_tendon" springlength="0.1">
      <site site="iliacus_r-P1"></site>
      <site site="iliacus_r-P2"></site>
      <site site="iliacus_r-P4"></site>
      <site site="iliacus_r-P5"></site>
    </spatial>
    <spatial name="psoas_r_tendon" springlength="0.16">
      <site site="psoas_r-P1"></site>
      <site site="psoas_r-P2"></site>
      <site site="psoas_r-P4"></site>
      <site site="psoas_r-P5"></site>
    </spatial>
    <spatial name="quad_fem_r_tendon" springlength="0.024">
      <site site="quad_fem_r-P1"></site>
      <site site="quad_fem_r-P2"></site>
    </spatial>
    <spatial name="gem_r_tendon" springlength="0.039">
      <site site="gem_r-P1"></site>
      <site site="gem_r-P2"></site>
    </spatial>
    <spatial name="peri_r_tendon" springlength="0.115">
      <site site="peri_r-P1"></site>
      <site site="peri_r-P2"></site>
      <site site="peri_r-P3"></site>
    </spatial>
    <spatial name="rect_fem_r_tendon" springlength="0.31">
      <site site="rect_fem_r-P1"></site>
      <site site="rect_fem_r-P3"></site>
    </spatial>
    <spatial name="vas_int_r_tendon" springlength="0.116">
      <site site="vas_int_r-P1"></site>
      <site site="vas_int_r-P2"></site>
      <site site="vas_int_r-P4"></site>
    </spatial>
    <spatial name="med_gas_r_tendon" springlength="0.36">
      <site site="med_gas_r-P1"></site>
      <site site="med_gas_r-P3"></site>
    </spatial>
    <spatial name="soleus_r_tendon" springlength="0.25">
      <site site="soleus_r-P1"></site>
      <site site="soleus_r-P2"></site>
    </spatial>
    <spatial name="tib_post_r_tendon" springlength="0.31">
      <site site="tib_post_r-P1"></site>
      <site site="tib_post_r-P2"></site>
      <site site="tib_post_r-P3"></site>
      <site site="tib_post_r-P4"></site>
    </spatial>
    <spatial name="tib_ant_r_tendon" springlength="0.223">
      <site site="tib_ant_r-P1"></site>
      <site site="tib_ant_r-P2"></site>
      <site site="tib_ant_r-P3"></site>
    </spatial>
    <spatial name="glut_med1_l_tendon" springlength="0.078">
      <site site="glut_med1_l-P1"></site>
      <site site="glut_med1_l-P2"></site>
    </spatial>
    <spatial name="glut_med2_l_tendon" springlength="0.053">
      <site site="glut_med2_l-P1"></site>
      <site site="glut_med2_l-P2"></site>
    </spatial>
    <spatial name="glut_med3_l_tendon" springlength="0.053">
      <site site="glut_med3_l-P1"></site>
      <site site="glut_med3_l-P2"></site>
    </spatial>
    <spatial name="bifemlh_l_tendon" springlength="0.326">
      <site site="bifemlh_l-P1"></site>
      <site site="bifemlh_l-P2"></site>
      <site site="bifemlh_l-P3"></site>
    </spatial>
    <spatial name="bifemsh_l_tendon" springlength="0.089">
      <site site="bifemsh_l-P1"></site>
      <site site="bifemsh_l-P2"></site>
      <site site="bifemsh_l-P3"></site>
    </spatial>
    <spatial name="sar_l_tendon" springlength="0.1">
      <site site="sar_l-P1"></site>
      <site site="sar_l-P2"></site>
      <site site="sar_l-P3"></site>
      <site site="sar_l-P4"></site>
      <site site="sar_l-P5"></site>
    </spatial>
    <spatial name="add_mag2_l_tendon" springlength="0.12">
      <site site="add_mag2_l-P1"></site>
      <site site="add_mag2_l-P2"></site>
    </spatial>
    <spatial name="tfl_l_tendon" springlength="0.425">
      <site site="tfl_l-P1"></site>
      <site site="tfl_l-P2"></site>
      <site site="tfl_l-P3"></site>
      <site site="tfl_l-P4"></site>
    </spatial>
    <spatial name="pect_l_tendon" springlength="0.033">
      <site site="pect_l-P1"></site>
      <site site="pect_l-P2"></site>
    </spatial>
    <spatial name="grac_l_tendon" springlength="0.126">
      <site site="grac_l-P1"></site>
      <site site="grac_l-P3"></site>
      <site site="grac_l-P4"></site>
    </spatial>
    <spatial name="glut_max1_l_tendon" springlength="0.125">
      <site site="glut_max1_l-P1"></site>
      <site site="glut_max1_l-P2"></site>
      <site site="glut_max1_l-P3"></site>
      <site site="glut_max1_l-P4"></site>
    </spatial>
    <spatial name="glut_max2_l_tendon" springlength="0.127">
      <site site="glut_max2_l-P1"></site>
      <site site="glut_max2_l-P2"></site>
      <site site="glut_max2_l-P3"></site>
      <site site="glut_max2_l-P4"></site>
    </spatial>
    <spatial name="glut_max3_l_tendon" springlength="0.145">
      <site site="glut_max3_l-P1"></site>
      <site site="glut_max3_l-P2"></site>
      <site site="glut_max3_l-P3"></site>
      <site site="glut_max3_l-P4"></site>
    </spatial>
    <spatial name="iliacus_l_tendon" springlength="0.1">
      <site site="iliacus_l-P1"></site>
      <site site="iliacus_l-P2"></site>
      <site site="iliacus_l-P4"></site>
      <site site="iliacus_l-P5"></site>
    </spatial>
    <spatial name="psoas_l_tendon" springlength="0.16">
      <site site="psoas_l-P1"></site>
      <site site="psoas_l-P2"></site>
      <site site="psoas_l-P4"></site>
      <site site="psoas_l-P5"></site>
    </spatial>
    <spatial name="quad_fem_l_tendon" springlength="0.024">
      <site site="quad_fem_l-P1"></site>
      <site site="quad_fem_l-P2"></site>
    </spatial>
    <spatial name="gem_l_tendon" springlength="0.039">
      <site site="gem_l-P1"></site>
      <site site="gem_l-P2"></site>
    </spatial>
    <spatial name="peri_l_tendon" springlength="0.115">
      <site site="peri_l-P1"></site>
      <site site="peri_l-P2"></site>
      <site site="peri_l-P3"></site>
    </spatial>
    <spatial name="rect_fem_l_tendon" springlength="0.31">
      <site site="rect_fem_l-P1"></site>
      <site site="rect_fem_l-P3"></site>
    </spatial>
    <spatial name="vas_int_l_tendon" springlength="0.116">
      <site site="vas_int_l-P1"></site>
      <site site="vas_int_l-P2"></site>
      <site site="vas_int_l-P4"></site>
    </spatial>
    <spatial name="med_gas_l_tendon" springlength="0.36">
      <site site="med_gas_l-P1"></site>
      <site site="med_gas_l-P3"></site>
    </spatial>
    <spatial name="soleus_l_tendon" springlength="0.25">
      <site site="soleus_l-P1"></site>
      <site site="soleus_l-P2"></site>
    </spatial>
    <spatial name="tib_post_l_tendon" springlength="0.31">
      <site site="tib_post_l-P1"></site>
      <site site="tib_post_l-P2"></site>
      <site site="tib_post_l-P3"></site>
      <site site="tib_post_l-P4"></site>
    </spatial>
    <spatial name="tib_ant_l_tendon" springlength="0.223">
      <site site="tib_ant_l-P1"></site>
      <site site="tib_ant_l-P2"></site>
      <site site="tib_ant_l-P3"></site>
    </spatial>
    <spatial name="ercspn_r_tendon" springlength="0.03">
      <site site="ercspn_r-P1"></site>
      <site site="ercspn_r-P2"></site>
    </spatial>
    <spatial name="ercspn_l_tendon" springlength="0.03">
      <site site="ercspn_l-P1"></site>
      <site site="ercspn_l-P2"></site>
    </spatial>
    <spatial name="intobl_r_tendon" springlength="0.1">
      <site site="intobl_r-P1"></site>
      <site site="intobl_r-P2"></site>
    </spatial>
    <spatial name="intobl_l_tendon" springlength="0.1">
      <site site="intobl_l-P1"></site>
      <site site="intobl_l-P2"></site>
    </spatial>
    <spatial name="extobl_r_tendon" springlength="0.14">
      <site site="extobl_r-P1"></site>
      <site site="extobl_r-P2"></site>
    </spatial>
    <spatial name="extobl_l_tendon" springlength="0.14">
      <site site="extobl_l-P1"></site>
      <site site="extobl_l-P2"></site>
    </spatial>
  </tendon>
  <actuator>
    <muscle name="glut_med1_r" tendon="glut_med1_r_tendon" class="muscle" timeconst="    0.01     0.04" ctrllimited="true" ctrlrange="       0        1"></muscle>
    <muscle name="glut_med2_r" tendon="glut_med2_r_tendon" class="muscle" timeconst="    0.01     0.04" ctrllimited="true" ctrlrange="       0        1"></muscle>
    <muscle name="glut_med3_r" tendon="glut_med3_r_tendon" class="muscle" timeconst="    0.01     0.04" ctrllimited="true" ctrlrange="       0        1"></muscle>
    <muscle name="bifemlh_r" tendon="bifemlh_r_tendon" class="muscle" timeconst="    0.01     0.04" ctrllimited="true" ctrlrange="       0        1"></muscle>
    <muscle name="bifemsh_r" tendon="bifemsh_r_tendon" class="muscle" timeconst="    0.01     0.04" ctrllimited="true" ctrlrange="       0        1"></muscle>
    <muscle name="sar_r" tendon="sar_r_tendon" class="muscle" timeconst="    0.01     0.04" ctrllimited="true" ctrlrange="       0        1"></muscle>
    <muscle name="add_mag2_r" tendon="add_mag2_r_tendon" class="muscle" timeconst="    0.01     0.04" ctrllimited="true" ctrlrange="       0        1"></muscle>
    <muscle name="tfl_r" tendon="tfl_r_tendon" class="muscle" timeconst="    0.01     0.04" ctrllimited="true" ctrlrange="       0        1"></muscle>
    <muscle name="pect_r" tendon="pect_r_tendon" class="muscle" timeconst="    0.01     0.04" ctrllimited="true" ctrlrange="       0        1"></muscle>
    <muscle name="grac_r" tendon="grac_r_tendon" class="muscle" timeconst="    0.01     0.04" ctrllimited="true" ctrlrange="       0        1"></muscle>
    <muscle name="glut_max1_r" tendon="glut_max1_r_tendon" class="muscle" timeconst="    0.01     0.04" ctrllimited="true" ctrlrange="       0        1"></muscle>
    <muscle name="glut_max2_r" tendon="glut_max2_r_tendon" class="muscle" timeconst="    0.01     0.04" ctrllimited="true" ctrlrange="       0        1"></muscle>
    <muscle name="glut_max3_r" tendon="glut_max3_r_tendon" class="muscle" timeconst="    0.01     0.04" ctrllimited="true" ctrlrange="       0        1"></muscle>
    <muscle name="iliacus_r" tendon="iliacus_r_tendon" class="muscle" timeconst="    0.01     0.04" ctrllimited="true" ctrlrange="       0        1"></muscle>
    <muscle name="psoas_r" tendon="psoas_r_tendon" class="muscle" timeconst="    0.01     0.04" ctrllimited="true" ctrlrange="       0        1"></muscle>
    <muscle name="quad_fem_r" tendon="quad_fem_r_tendon" class="muscle" timeconst="    0.01     0.04" ctrllimited="true" ctrlrange="       0        1"></muscle>
    <muscle name="gem_r" tendon="gem_r_tendon" class="muscle" timeconst="    0.01     0.04" ctrllimited="true" ctrlrange="       0        1"></muscle>
    <muscle name="peri_r" tendon="peri_r_tendon" class="muscle" timeconst="    0.01     0.04" ctrllimited="true" ctrlrange="       0        1"></muscle>
    <muscle name="rect_fem_r" tendon="rect_fem_r_tendon" class="muscle" timeconst="    0.01     0.04" ctrllimited="true" ctrlrange="       0        1"></muscle>
    <muscle name="vas_int_r" tendon="vas_int_r_tendon" class="muscle" timeconst="    0.01     0.04" ctrllimited="true" ctrlrange="       0        1"></muscle>
    <muscle name="med_gas_r" tendon="med_gas_r_tendon" class="muscle" timeconst="    0.01     0.04" ctrllimited="true" ctrlrange="       0        1"></muscle>
    <muscle name="soleus_r" tendon="soleus_r_tendon" class="muscle" timeconst="    0.01     0.04" ctrllimited="true" ctrlrange="       0        1"></muscle>
    <muscle name="tib_post_r" tendon="tib_post_r_tendon" class="muscle" timeconst="    0.01     0.04" ctrllimited="true" ctrlrange="       0        1"></muscle>
    <muscle name="tib_ant_r" tendon="tib_ant_r_tendon" class="muscle" timeconst="    0.01     0.04" ctrllimited="true" ctrlrange="       0        1"></muscle>
    <muscle name="glut_med1_l" tendon="glut_med1_l_tendon" class="muscle" timeconst="    0.01     0.04" ctrllimited="true" ctrlrange="       0        1"></muscle>
    <muscle name="glut_med2_l" tendon="glut_med2_l_tendon" class="muscle" timeconst="    0.01     0.04" ctrllimited="true" ctrlrange="       0        1"></muscle>
    <muscle name="glut_med3_l" tendon="glut_med3_l_tendon" class="muscle" timeconst="    0.01     0.04" ctrllimited="true" ctrlrange="       0        1"></muscle>
    <muscle name="bifemlh_l" tendon="bifemlh_l_tendon" class="muscle" timeconst="    0.01     0.04" ctrllimited="true" ctrlrange="       0        1"></muscle>
    <muscle name="bifemsh_l" tendon="bifemsh_l_tendon" class="muscle" timeconst="    0.01     0.04" ctrllimited="true" ctrlrange="       0        1"></muscle>
    <muscle name="sar_l" tendon="sar_l_tendon" class="muscle" timeconst="    0.01     0.04" ctrllimited="true" ctrlrange="       0        1"></muscle>
    <muscle name="add_mag2_l" tendon="add_mag2_l_tendon" class="muscle" timeconst="    0.01     0.04" ctrllimited="true" ctrlrange="       0        1"></muscle>
    <muscle name="tfl_l" tendon="tfl_l_tendon" class="muscle" timeconst="    0.01     0.04" ctrllimited="true" ctrlrange="       0        1"></muscle>
    <muscle name="pect_l" tendon="pect_l_tendon" class="muscle" timeconst="    0.01     0.04" ctrllimited="true" ctrlrange="       0        1"></muscle>
    <muscle name="grac_l" tendon="grac_l_tendon" class="muscle" timeconst="    0.01     0.04" ctrllimited="true" ctrlrange="       0        1"></muscle>
    <muscle name="glut_max1_l" tendon="glut_max1_l_tendon" class="muscle" timeconst="    0.01     0.04" ctrllimited="true" ctrlrange="       0        1"></muscle>
    <muscle name="glut_max2_l" tendon="glut_max2_l_tendon" class="muscle" timeconst="    0.01     0.04" ctrllimited="true" ctrlrange="       0        1"></muscle>
    <muscle name="glut_max3_l" tendon="glut_max3_l_tendon" class="muscle" timeconst="    0.01     0.04" ctrllimited="true" ctrlrange="       0        1"></muscle>
    <muscle name="iliacus_l" tendon="iliacus_l_tendon" class="muscle" timeconst="    0.01     0.04" ctrllimited="true" ctrlrange="       0        1"></muscle>
    <muscle name="psoas_l" tendon="psoas_l_tendon" class="muscle" timeconst="    0.01     0.04" ctrllimited="true" ctrlrange="       0        1"></muscle>
    <muscle name="quad_fem_l" tendon="quad_fem_l_tendon" class="muscle" timeconst="    0.01     0.04" ctrllimited="true" ctrlrange="       0        1"></muscle>
    <muscle name="gem_l" tendon="gem_l_tendon" class="muscle" timeconst="    0.01     0.04" ctrllimited="true" ctrlrange="       0        1"></muscle>
    <muscle name="peri_l" tendon="peri_l_tendon" class="muscle" timeconst="    0.01     0.04" ctrllimited="true" ctrlrange="       0        1"></muscle>
    <muscle name="rect_fem_l" tendon="rect_fem_l_tendon" class="muscle" timeconst="    0.01     0.04" ctrllimited="true" ctrlrange="       0        1"></muscle>
    <muscle name="vas_int_l" tendon="vas_int_l_tendon" class="muscle" timeconst="    0.01     0.04" ctrllimited="true" ctrlrange="       0        1"></muscle>
    <muscle name="med_gas_l" tendon="med_gas_l_tendon" class="muscle" timeconst="    0.01     0.04" ctrllimited="true" ctrlrange="       0        1"></muscle>
    <muscle name="soleus_l" tendon="soleus_l_tendon" class="muscle" timeconst="    0.01     0.04" ctrllimited="true" ctrlrange="       0        1"></muscle>
    <muscle name="tib_post_l" tendon="tib_post_l_tendon" class="muscle" timeconst="    0.01     0.04" ctrllimited="true" ctrlrange="       0        1"></muscle>
    <muscle name="tib_ant_l" tendon="tib_ant_l_tendon" class="muscle" timeconst="    0.01     0.04" ctrllimited="true" ctrlrange="       0        1"></muscle>
    <muscle name="ercspn_r" tendon="ercspn_r_tendon" class="muscle" timeconst="    0.01     0.04" ctrllimited="true" ctrlrange="       0        1"></muscle>
    <muscle name="ercspn_l" tendon="ercspn_l_tendon" class="muscle" timeconst="    0.01     0.04" ctrllimited="true" ctrlrange="       0        1"></muscle>
    <muscle name="intobl_r" tendon="intobl_r_tendon" class="muscle" timeconst="    0.01     0.04" ctrllimited="true" ctrlrange="       0        1"></muscle>
    <muscle name="intobl_l" tendon="intobl_l_tendon" class="muscle" timeconst="    0.01     0.04" ctrllimited="true" ctrlrange="       0        1"></muscle>
    <muscle name="extobl_r" tendon="extobl_r_tendon" class="muscle" timeconst="    0.01     0.04" ctrllimited="true" ctrlrange="       0        1"></muscle>
    <muscle name="extobl_l" tendon="extobl_l_tendon" class="muscle" timeconst="    0.01     0.04" ctrllimited="true" ctrlrange="       0        1"></muscle>
  </actuator>
  <equality>
    <joint name="knee_angle_r_translation2_constraint" active="true" joint1="knee_angle_r_translation2" joint2="knee_angle_r" polycoef="-0.395713 0.00341345 -0.00558653 0.000669664 0.000567409" solimp="0.9999 0.9999 0.001 0.5 2"></joint>
    <joint name="knee_angle_r_translation1_constraint" active="true" joint1="knee_angle_r_translation1" joint2="knee_angle_r" polycoef="-0.00363925 -0.00626677 0.00280689 0.00134038 -0.000677624" solimp="0.9999 0.9999 0.001 0.5 2"></joint>
    <joint name="knee_angle_l_translation2_constraint" active="true" joint1="knee_angle_l_translation2" joint2="knee_angle_l" polycoef="-0.395713 0.00341345 -0.00558653 0.000669664 0.000567409" solimp="0.9999 0.9999 0.001 0.5 2"></joint>
    <joint name="knee_angle_l_translation1_constraint" active="true" joint1="knee_angle_l_translation1" joint2="knee_angle_l" polycoef="-0.00363925 -0.00626677 0.00280689 0.00134038 -0.000677624" solimp="0.9999 0.9999 0.001 0.5 2"></joint>
    <weld name="origin_to_worldbody" body1="pelvis" active="false"></weld>
  </equality>
</mujoco>